2023-11-07 21:00:41,068 INFO    StreamThr :2131 [internal.py:wandb_internal():86] W&B internal server running at pid: 2131, started at: 2023-11-07 21:00:41.068299
2023-11-07 21:00:41,069 DEBUG   HandlerThread:2131 [handler.py:handle_request():144] handle_request: status
2023-11-07 21:00:41,077 INFO    WriterThread:2131 [datastore.py:open_for_write():85] open: /Users/junhyeonbae/PycharmProjects/MAgent2_hetero/wandb/run-20231107_210041-g2ydg9hl/run-g2ydg9hl.wandb
2023-11-07 21:00:41,078 DEBUG   SenderThread:2131 [sender.py:send():379] send: header
2023-11-07 21:00:41,098 DEBUG   SenderThread:2131 [sender.py:send():379] send: run
2023-11-07 21:00:41,567 ERROR   SenderThread:2131 [internal_api.py:execute():326] 403 response executing GraphQL.
2023-11-07 21:00:41,568 ERROR   SenderThread:2131 [internal_api.py:execute():327] {"errors":[{"message":"permission denied","path":["upsertBucket"],"extensions":{"code":"PERMISSION_ERROR"}}],"data":{"upsertBucket":null}}
2023-11-07 21:00:41,568 ERROR   SenderThread:2131 [sender.py:send_run():976] It appears that you do not have permission to access the requested resource. Please reach out to the project owner to grant you access. If you have the correct permissions, verify that there are no issues with your networking setup.(Error 403: Forbidden)
Traceback (most recent call last):
  File "/Users/junhyeonbae/anaconda3/envs/MAgent2_hetero/lib/python3.8/site-packages/wandb/sdk/lib/retry.py", line 131, in __call__
    result = self._call_fn(*args, **kwargs)
  File "/Users/junhyeonbae/anaconda3/envs/MAgent2_hetero/lib/python3.8/site-packages/wandb/sdk/internal/internal_api.py", line 323, in execute
    return self.client.execute(*args, **kwargs)  # type: ignore
  File "/Users/junhyeonbae/anaconda3/envs/MAgent2_hetero/lib/python3.8/site-packages/wandb/vendor/gql-0.2.0/wandb_gql/client.py", line 52, in execute
    result = self._get_result(document, *args, **kwargs)
  File "/Users/junhyeonbae/anaconda3/envs/MAgent2_hetero/lib/python3.8/site-packages/wandb/vendor/gql-0.2.0/wandb_gql/client.py", line 60, in _get_result
    return self.transport.execute(document, *args, **kwargs)
  File "/Users/junhyeonbae/anaconda3/envs/MAgent2_hetero/lib/python3.8/site-packages/wandb/sdk/lib/gql_request.py", line 56, in execute
    request.raise_for_status()
  File "/Users/junhyeonbae/anaconda3/envs/MAgent2_hetero/lib/python3.8/site-packages/requests/models.py", line 1021, in raise_for_status
    raise HTTPError(http_error_msg, response=self)
requests.exceptions.HTTPError: 403 Client Error: Forbidden for url: https://api.wandb.ai/graphql

During handling of the above exception, another exception occurred:

Traceback (most recent call last):
  File "/Users/junhyeonbae/anaconda3/envs/MAgent2_hetero/lib/python3.8/site-packages/wandb/sdk/internal/sender.py", line 974, in send_run
    self._init_run(run, config_value_dict)
  File "/Users/junhyeonbae/anaconda3/envs/MAgent2_hetero/lib/python3.8/site-packages/wandb/sdk/internal/sender.py", line 1012, in _init_run
    server_run, inserted, server_messages = self._api.upsert_run(
  File "/Users/junhyeonbae/anaconda3/envs/MAgent2_hetero/lib/python3.8/site-packages/wandb/apis/normalize.py", line 73, in wrapper
    raise err
  File "/Users/junhyeonbae/anaconda3/envs/MAgent2_hetero/lib/python3.8/site-packages/wandb/apis/normalize.py", line 41, in wrapper
    return func(*args, **kwargs)
  File "/Users/junhyeonbae/anaconda3/envs/MAgent2_hetero/lib/python3.8/site-packages/wandb/sdk/internal/internal_api.py", line 1958, in upsert_run
    response = self.gql(
  File "/Users/junhyeonbae/anaconda3/envs/MAgent2_hetero/lib/python3.8/site-packages/wandb/sdk/internal/internal_api.py", line 295, in gql
    ret = self._retry_gql(
  File "/Users/junhyeonbae/anaconda3/envs/MAgent2_hetero/lib/python3.8/site-packages/wandb/sdk/lib/retry.py", line 147, in __call__
    retry_timedelta_triggered = check_retry_fn(e)
  File "/Users/junhyeonbae/anaconda3/envs/MAgent2_hetero/lib/python3.8/site-packages/wandb/util.py", line 956, in check_retry_fn
    return fallback_retry_fn(e)
  File "/Users/junhyeonbae/anaconda3/envs/MAgent2_hetero/lib/python3.8/site-packages/wandb/util.py", line 898, in no_retry_auth
    raise CommError(
wandb.errors.CommError: It appears that you do not have permission to access the requested resource. Please reach out to the project owner to grant you access. If you have the correct permissions, verify that there are no issues with your networking setup.(Error 403: Forbidden)
2023-11-07 21:00:41,669 DEBUG   HandlerThread:2131 [handler.py:handle_request():144] handle_request: shutdown
2023-11-07 21:00:41,670 INFO    HandlerThread:2131 [handler.py:finish():857] shutting down handler
2023-11-07 21:00:42,098 INFO    WriterThread:2131 [datastore.py:close():294] close: /Users/junhyeonbae/PycharmProjects/MAgent2_hetero/wandb/run-20231107_210041-g2ydg9hl/run-g2ydg9hl.wandb
2023-11-07 21:00:42,580 INFO    SenderThread:2131 [sender.py:finish():1552] shutting down sender
